import React from 'react';
import { render, screen, fireEvent } from '@testing-library/react';
import '@testing-library/jest-dom';
import ErrorBoundary from './ErrorBoundary';

// Component that throws an error for testing
const ThrowError: React.FC<{ shouldThrow: boolean }> = ({ shouldThrow }) => {
  if (shouldThrow) {
    throw new Error('Test error');
  }
  return <div>No error</div>;
};

describe('ErrorBoundary', () => {
  // Suppress console.error for these tests
  const originalError = console.error;
  beforeAll(() => {
    console.error = jest.fn();
  });

  afterAll(() => {
    console.error = originalError;
  });

  it('renders children when there is no error', () => {
    render(
      <ErrorBoundary>
        <ThrowError shouldThrow={false} />
      </ErrorBoundary>
    );

    expect(screen.getByText('No error')).toBeInTheDocument();
  });

  it('renders error UI when there is an error', () => {
    render(
      <ErrorBoundary>
        <ThrowError shouldThrow={true} />
      </ErrorBoundary>
    );

    expect(screen.getByText('Something went wrong')).toBeInTheDocument();
    expect(screen.getByText(/An unexpected error occurred/)).toBeInTheDocument();
    expect(screen.getByRole('button', { name: 'Try Again' })).toBeInTheDocument();
  });

  it('renders custom fallback when provided', () => {
    const customFallback = <div>Custom error message</div>;

    render(
      <ErrorBoundary fallback={customFallback}>
        <ThrowError shouldThrow={true} />
      </ErrorBoundary>
    );

    expect(screen.getByText('Custom error message')).toBeInTheDocument();
    expect(screen.queryByText('Something went wrong')).not.toBeInTheDocument();
  });

  it('calls onError callback when error occurs', () => {
    const onError = jest.fn();

    render(
      <ErrorBoundary onError={onError}>
        <ThrowError shouldThrow={true} />
      </ErrorBoundary>
    );

    expect(onError).toHaveBeenCalledWith(
      expect.any(Error),
      expect.objectContaining({
        componentStack: expect.any(String)
      })
    );
  });

  it('resets error state when retry button is clicked', () => {
    const TestComponent: React.FC = () => {
      const [shouldThrow, setShouldThrow] = React.useState(true);

      React.useEffect(() => {
        // Reset the error after a short delay to simulate recovery
        if (shouldThrow) {
          const timer = setTimeout(() => setShouldThrow(false), 100);
          return () => clearTimeout(timer);
        }
      }, [shouldThrow]);

      return <ThrowError shouldThrow={shouldThrow} />;
    };

    render(
      <ErrorBoundary>
        <TestComponent />
      </ErrorBoundary>
    );

    // Error should be displayed initially
    expect(screen.getByText('Something went wrong')).toBeInTheDocument();

    // Click retry button
    fireEvent.click(screen.getByRole('button', { name: 'Try Again' }));

    // Component should attempt to re-render
    // Note: In a real scenario, the component would need to handle the retry logic
  });

  it('shows error details in development mode', () => {
    const originalEnv = process.env.NODE_ENV;
    process.env.NODE_ENV = 'development';

    render(
      <ErrorBoundary>
        <ThrowError shouldThrow={true} />
      </ErrorBoundary>
    );

    expect(screen.getByText('Error Details (Development Mode)')).toBeInTheDocument();

    process.env.NODE_ENV = originalEnv;
  });

  it('hides error details in production mode', () => {
    const originalEnv = process.env.NODE_ENV;
    process.env.NODE_ENV = 'production';

    render(
      <ErrorBoundary>
        <ThrowError shouldThrow={true} />
      </ErrorBoundary>
    );

    expect(screen.queryByText('Error Details (Development Mode)')).not.toBeInTheDocument();

    process.env.NODE_ENV = originalEnv;
  });
});